Workbook

Sheet Démarcharge SDC 2026
A1: Membre de SDC | B1: Catégorie | C1: Château / Entreprise | D1: Apparaît dans la bible ? | E1: Statut de la demande | F1: Pôle concerné | G1: Prénom | H1: Nom | I1: Région | J1: Mail | K1: Poste | L1: Téléphone | M1: Nombre de bouteilles | N1: Logistique | O1: Suivi des étapes | P1: Contexte de la demande/commentaires | Q1: Région/Appellation | R1: Aspect RSE | S1: Possible de démarcher à nouveau ? | T1: Si oui, quel type ?
B2: catégorie | C2: Domaine Eric Sage | D2: =IF(COUNTIF('LA BIBLE'!C:C,C2)>0,"Oui","Non") -> Non | E2: Non contacté | F2: Pôle concerné
B3: catégorie | C3: Domaine L'Orée du Sabia | D3: =IF(COUNTIF('LA BIBLE'!C:C,C3)>0,"Oui","Non") -> Non | E3: Non contacté | F3: Pôle concerné
B4: catégorie | C4: Vignobles Mercier | D4: =IF(COUNTIF('LA BIBLE'!C:C,C4)>0,"Oui","Non") -> Non | E4: Non contacté | F4: Pôle concerné
B5: catégorie | C5: Domaine Coirier | D5: =IF(COUNTIF('LA BIBLE'!C:C,C5)>0,"Oui","Non") -> Non | E5: Non contacté | F5: Pôle concerné
B6: catégorie | C6: Domaine de la Barbinière | D6: =IF(COUNTIF('LA BIBLE'!C:C,C6)>0,"Oui","Non") -> Non | E6: Non contacté | F6: Pôle concerné
B7: catégorie | C7: Domaine Georges Vernay | D7: =IF(COUNTIF('LA BIBLE'!C:C,C7)>0,"Oui","Non") -> Non | E7: Non contacté | F7: Pôle concerné
B8: catégorie | C8: Domaine Jean-Michel Gerin | D8: =IF(COUNTIF('LA BIBLE'!C:C,C8)>0,"Oui","Non") -> Non | E8: Non contacté | F8: Pôle concerné
B9: catégorie | C9: Domaine Guigal | D9: =IF(COUNTIF('LA BIBLE'!C:C,C9)>0,"Oui","Non") -> Non | E9: Non contacté | F9: Pôle concerné
B10: catégorie | C10: Domaine Pierre Gaillard | D10: =IF(COUNTIF('LA BIBLE'!C:C,C10)>0,"Oui","Non") -> Non | E10: Non contacté | F10: Pôle concerné
B11: catégorie | C11: Domaine Bernard Gripa | D11: =IF(COUNTIF('LA BIBLE'!C:C,C11)>0,"Oui","Non") -> Non | E11: Non contacté | F11: Pôle concerné
B12: catégorie | C12: Domaine Alain Graillot | D12: =IF(COUNTIF('LA BIBLE'!C:C,C12)>0,"Oui","Non") -> Non | E12: Non contacté | F12: Pôle concerné
B13: catégorie | C13: Domaine Alain Voge | D13: =IF(COUNTIF('LA BIBLE'!C:C,C13)>0,"Oui","Non") -> Non | E13: Non contacté | F13: Pôle concerné
... B47: catégorie | C47: Domaine Giudicelli | D47: =IF(COUNTIF('LA BIBLE'!C:C,C47)>0,"Oui","Non") -> Non | E47: Non contacté | F47: Pôle concerné
B48: catégorie | C48: Domaine Devichi
B49: catégorie | C49: Domaine Poli
B50: catégorie | C50: Domaine Yves Leccia
B51: catégorie | C51: Domaine Lazzarini
B52: catégorie | C52: Clos de Bernardi
B53: catégorie | C53: Domaine Montemagni
B54: catégorie | C54: Clos Alivu
B55: catégorie | C55: Clos Venturi
B56: catégorie | C56: Clos Marfisi
B57: catégorie | C57: Domaine Comte Abbatucci
B58: catégorie | C58: Clos Capitoro
B59: catégorie | C59: Domaine Peraldi
... B410: catégorie | C410: Château de Teste

Sheet LA BIBLE
A1: Membre de SDC | B1: Catégorie | C1: Château / Entreprise | D1: Statut de la demande | E1: Pôle concerné | F1: Prénom | G1: Nom | H1: Région | I1: Mail | J1: Poste | K1: Téléphone | L1: Nombre de bouteilles | M1: Logistique | N1: Suivi des étapes | O1: Contexte de la demande/commentaires | P1: Région/Appellation | Q1: Aspect RSE | R1: Possible de démarcher à nouveau ? | S1: Si oui, quel type ?
A2: Arnaud | B2: Démarchage financier | C2: Cabinet Julhiet Sterwen | D2: Contacté, en discussions | E2: Défi de Bacchus | F2: Ludivine | G2: Toutounji (contact de l'emlyon en attendant qu'elle nous transmette au contact du cabinet) | I2: toutounji@em-lyon.com | J2: Directrice adjointe en charge des partenariats entreprises | O2: La responsable des relations exterieurs de l'em nous a informé de l'interet du cabinet d'apporter un soutien financier à l'asso d'oenologie de l'école
A3: Antoine/Cédric | B3: Démarchage en nature | C3: Château André Ziltener | D3: Contacté, sans réponse | E3: Défi de Bacchus
A4: Antoine/Cédric | B4: Démarchage en nature | C4: Domaine Alain Zorninger | D4: Contacté, sans réponse | E4: Défi de Bacchus
A5: Antoine/Cédric | B5: Démarchage en nature | C5: Domaine Pascal Bonhomme | D5: Contacté, sans réponse | E5: Défi de Bacchus
A6: Antoine/Cédric | B6: Démarchage en nature | C6: Domaine de Naisse - Brenot Béranger | D6: Contacté, sans réponse | E6: Défi de Bacchus
A7: Antoine/Cédric | B7: Démarchage en nature | C7: Cave de la Vigne Blanche | D7: Contacté, sans réponse | E7: Défi de Bacchus
A8: Antoine/Cédric | B8: Démarchage en nature | C8: Cave de Viré | D8: Contacté, sans réponse | E8: Défi de Bacchus
A9: Antoine/Cédric | B9: Démarchage en nature | C9: Marchand tawse | D9: Contacté, sans réponse | E9: Défi de Bacchus
A10: Antoine/Cédric | B10: Démarchage en nature | C10: Domaine Frantz Chagnoleau | D10: Contacté, sans réponse | E10: Défi de Bacchus
A11: Antoine/Cédric | B11: Démarchage en nature | C11: Olivier Leflaive | D11: Validé | E11: Défi de Bacchus | L11: 6 | M11: Récupérées par Allan | N11: 6 bouteilles
A12: Antoine/Cédric | B12: Démarchage en nature | C12: Domaine Sainte-Barbe | D12: Contacté, sans réponse | E12: Défi de Bacchus
A13: Antoine/Cédric | B13: Démarchage en nature | C13: Domaine Les Fauvettes | D13: Contacté, sans réponse | E13: Défi de Bacchus
A14: Antoine/Cédric | B14: Démarchage en nature | C14: Domaine Cordier | D14: Contacté, sans réponse | E14: Défi de Bacchus
A15: Antoine/Cédric | B15: Démarchage en nature | C15: Domaine des Gandines | D15: Contacté, sans réponse | E15: Défi de Bacchus
A16: Antoine/Cédric | B16: Démarchage en nature | C16: Domaine Edouard Delaunay | D16: Contacté, sans réponse | E16: Défi de Bacchus
A17: Antoine/Cédric | B17: Démarchage en nature | C17: Domaine du Mortier | D17: Contacté, sans réponse | E17: Défi de Bacchus
A18: Antoine/Cédric | B18: Démarchage en nature | C18: Chai Duchet | D18: Contacté, sans réponse | E18: Défi de Bacchus
A19: Antoine/Cédric | B19: Démarchage en nature | C19: Domaine Le Virolys | D19: Contacté, sans réponse | E19: Défi de Bacchus
A20: Antoine/Cédric | B20: Démarchage en nature | C20: Domaine Gondard-Perrin | D20: Contacté, sans réponse | E20: Défi de Bacchus
A21: Antoine/Cédric | B21: Démarchage en nature | C21: Domaine Lucie et Stéphane Guillemin. | D21: Contacté, sans réponse | E21: Défi de Bacchus
A22: Antoine/Cédric | B22: Démarchage en nature | C22: Domaine Mee Godard | D22: Validé | E22: Défi de Bacchus | L22: 3 | M22: Récupérées par Allan | N22: 3 bouteilles | R22: Non
A23: Antoine/Cédric | B23: Démarchage en nature | C23: Château de Pibarnon | D23: Contacté, refus | E23: Défi de Bacchus
A24: Antoine/Cédric | B24: Démarchage en nature | C24: Domaine La Borderie | D24: Contacté, refus | E24: Défi de Bacchus
A25: Antoine/Cédric | B25: Démarchage en nature | C25: le Domaine Ostertag | D25: Contacté, refus | E25: Défi de Bacchus
A26: Antoine/Cédric | B26: Démarchage en nature | C26: le Clos Triguedina | D26: Contacté, refus | E26: Défi de Bacchus
A27: Antoine/Cédric | B27: Démarchage en nature | C27: Château du Cèdre | D27: Validé | E27: Défi de Bacchus | L27: 3 | M27: Récupérées par Allan | N27: 3 bouteilles | R27: Non
A28: Antoine/Cédric | B28: Démarchage en nature | C28: De Peres | D28: Contacté, refus | E28: Défi de Bacchus
A29: Antoine/Cédric | B29: Démarchage en nature | C29: Domaine Wengier | D29: Validé | E29: Défi de Bacchus | L29: 6 | M29: Récupérées par Jeanne | N29: 6 bouteilles | R29: Oui
A30: Antoine/Cédric | B30: Démarchage en nature | C30: Les Roques de Cana | D30: Validé | E30: Défi de Bacchus | L30: 6 | M30: Récupérées par Allan | N30: 6 bouteilles
A31: Antoine/Cédric | B31: Démarchage en nature | C31: Vignoble Angst | D31: Contacté, refus | E31: Défi de Bacchus
A32: Antoine/Cédric | B32: Démarchage en nature | C32: Amandine Scarone | D32: Contacté, sans réponse | E32: Défi de Bacchus
A33: Antoine/Cédric | B33: Démarchage en nature | C33: Ampelide | D33: Contacté, sans réponse | E33: Défi de Bacchus
A34: Antoine/Cédric | B34: Démarchage en nature | C34: Amphore De Beausoleil | D34: Contacté, sans réponse | E34: Défi de Bacchus
A35: Antoine/Cédric | B35: Démarchage en nature | C35: Angueiroun Sélections | D35: Contacté, sans réponse | E35: Défi de Bacchus
A36: Antoine/Cédric | B36: Démarchage en nature | C36: Annibals Sas | D36: Contacté, sans réponse | E36: Défi de Bacchus
A37: Antoine/Cédric | B37: Démarchage en nature | C37: Anthony Mati | D37: Contacté, sans réponse | E37: Défi de Bacchus
A38: Antoine/Cédric | B38: Démarchage en nature | C38: Aquadro Delphine | D38: Contacté, sans réponse | E38: Défi de Bacchus
A39: Antoine/Cédric | B39: Démarchage en nature | C39: Azur Wine Selection | D39: Contacté, sans réponse | E39: Défi de Bacchus
A40: Antoine/Cédric | B40: Démarchage en nature | C40: Bagarry - Gueguen | D40: Contacté, sans réponse | E40: Défi de Bacchus
...

Sheet Feuille 2
A1: Membre de SDC | B1: Catégorie | C1: Château / Entreprise | D1: Statut de la demande | E1: Pôle concerné | F1: Prénom | G1: Nom | H1: Région | I1: Mail | J1: Poste | K1: Téléphone | L1: Nombre de bouteilles | M1: Logistique | N1: Suivi des étapes | O1: Contexte de la demande/commentaires | P1: Région/Appellation | Q1: Aspect RSE | R1: Possible de démarcher à nouveau ? | S1: Si oui, quel type ?
A2: Arnaud | B2: Démarchage financier | C2: Cabinet Julhiet Sterwen | D2: Contacté, en discussions | E2: Défi de Bacchus | F2: Ludivine | G2: Toutounji (contact de l'emlyon en attendant qu'elle nous transmette au contact du cabinet) | I2: toutounji@em-lyon.com | J2: Directrice adjointe en charge des partenariats entreprises | O2: La responsable des relations exterieurs de l'em nous a informé de l'interet du cabinet d'apporter un soutien financier à l'asso d'oenologie de l'école
A3: Antoine/Cédric | B3: Démarchage en nature | C3: Château André Ziltener | D3: Contacté, sans réponse | E3: Défi de Bacchus
A4: Antoine/Cédric | B4: Démarchage en nature | C4: Domaine Alain Zorninger | D4: Contacté, sans réponse | E4: Défi de Bacchus
A5: Antoine/Cédric | B5: Démarchage en nature | C5: Domaine Pascal Bonhomme | D5: Contacté, sans réponse | E5: Défi de Bacchus
A6: Antoine/Cédric | B6: Démarchage en nature | C6: Domaine de Naisse - Brenot Béranger | D6: Contacté, sans réponse | E6: Défi de Bacchus
A7: Antoine/Cédric | B7: Démarchage en nature | C7: Cave de la Vigne Blanche | D7: Contacté, sans réponse | E7: Défi de Bacchus
A8: Antoine/Cédric | B8: Démarchage en nature | C8: Cave de Viré | D8: Contacté, sans réponse | E8: Défi de Bacchus
A9: Antoine/Cédric | B9: Démarchage en nature | C9: Marchand tawse | D9: Contacté, sans réponse | E9: Défi de Bacchus
A10: Antoine/Cédric | B10: Démarchage en nature | C10: Domaine Frantz Chagnoleau | D10: Contacté, sans réponse | E10: Défi de Bacchus
A11: Antoine/Cédric | B11: Démarchage en nature | C11: Olivier Leflaive | D11: Validé | E11: Défi de Bacchus | L11: 6 | M11: Récupérées par Allan | N11: 6 bouteilles
A12: Antoine/Cédric | B12: Démarchage en nature | C12: Domaine Sainte-Barbe | D12: Contacté, sans réponse | E12: Défi de Bacchus
A13: Antoine/Cédric | B13: Démarchage en nature | C13: Domaine Les Fauvettes | D13: Contacté, sans réponse | E13: Défi de Bacchus
A14: Antoine/Cédric | B14: Démarchage en nature | C14: Domaine Cordier | D14: Contacté, sans réponse | E14: Défi de Bacchus
A15: Antoine/Cédric | B15: Démarchage en nature | C15: Domaine des Gandines | D15: Contacté, sans réponse | E15: Défi de Bacchus
A16: Antoine/Cédric | B16: Démarchage en nature | C16: Domaine Edouard Delaunay | D16: Contacté, sans réponse | E16: Défi de Bacchus
A17: Antoine/Cédric | B17: Démarchage en nature | C17: Domaine du Mortier | D17: Contacté, sans réponse | E17: Défi de Bacchus
A18: Antoine/Cédric | B18: Démarchage en nature | C18: Chai Duchet | D18: Contacté, sans réponse | E18: Défi de Bacchus
A19: Antoine/Cédric | B19: Démarchage en nature | C19: Domaine Le Virolys | D19: Contacté, sans réponse | E19: Défi de Bacchus
A20: Antoine/Cédric | B20: Démarchage en nature | C20: Domaine Gondard-Perrin | D20: Contacté, sans réponse | E20: Défi de Bacchus
A21: Antoine/Cédric | B21: Démarchage en nature | C21: Domaine Lucie et Stéphane Guillemin. | D21: Contacté, sans réponse | E21: Défi de Bacchus
A22: Antoine/Cédric | B22: Démarchage en nature | C22: Domaine Mee Godard | D22: Validé | E22: Défi de Bacchus | L22: 3 | M22: Récupérées par Allan | N22: 3 bouteilles | R22: Non
A23: Antoine/Cédric | B23: Démarchage en nature | C23: Château de Pibarnon | D23: Contacté, refus | E23: Défi de Bacchus
A24: Antoine/Cédric | B24: Démarchage en nature | C24: Domaine La Borderie | D24: Contacté, refus | E24: Défi de Bacchus
A25: Antoine/Cédric | B25: Démarchage en nature | C25: le Domaine Ostertag | D25: Contacté, refus | E25: Défi de Bacchus
A26: Antoine/Cédric | B26: Démarchage en nature | C26: le Clos Triguedina | D26: Contacté, refus | E26: Défi de Bacchus
A27: Antoine/Cédric | B27: Démarchage en nature | C27: Château du Cèdre | D27: Validé | E27: Défi de Bacchus | L27: 3 | M27: Récupérées par Allan | N27: 3 bouteilles | R27: Non
A28: Antoine/Cédric | B28: Démarchage en nature | C28: De Peres | D28: Contacté, refus | E28: Défi de Bacchus
A29: Antoine/Cédric | B29: Démarchage en nature | C29: Domaine Wengier | D29: Validé | E29: Défi de Bacchus | L29: 6 | M29: Récupérées par Jeanne | N29: 6 bouteilles | R29: Oui
A30: Antoine/Cédric | B30: Démarchage en nature | C30: Les Roques de Cana | D30: Validé | E30: Défi de Bacchus | L30: 6 | M30: Récupérées par Allan | N30: 6 bouteilles
A31: Antoine/Cédric | B31: Démarchage en nature | C31: Vignoble Angst | D31: Contacté, refus | E31: Défi de Bacchus
A32: Antoine/Cédric | B32: Démarchage en nature | C32: Amandine Scarone | D32: Contacté, sans réponse | E32: Défi de Bacchus
A33: Antoine/Cédric | B33: Démarchage en nature | C33: Ampelide | D33: Contacté, sans réponse | E33: Défi de Bacchus
A34: Antoine/Cédric | B34: Démarchage en nature | C34: Amphore De Beausoleil | D34: Contacté, sans réponse | E34: Défi de Bacchus
A35: Antoine/Cédric | B35: Démarchage en nature | C35: Angueiroun Sélections | D35: Contacté, sans réponse | E35: Défi de Bacchus
A36: Antoine/Cédric | B36: Démarchage en nature | C36: Annibals Sas | D36: Contacté, sans réponse | E36: Défi de Bacchus
A37: Antoine/Cédric | B37: Démarchage en nature | C37: Anthony Mati | D37: Contacté, sans réponse | E37: Défi de Bacchus
A38: Antoine/Cédric | B38: Démarchage en nature | C38: Aquadro Delphine | D38: Contacté, sans réponse | E38: Défi de Bacchus
A39: Antoine/Cédric | B39: Démarchage en nature | C39: Azur Wine Selection | D39: Contacté, sans réponse | E39: Défi de Bacchus
A40: Antoine/Cédric | B40: Démarchage en nature | C40: Bagarry - Gueguen | D40: Contacté, sans réponse | E40: Défi de Bacchus
...

Sheet Feuille 4
A1: Flight bulles: 2 champagnes 1 crémant
B2: Remarques
A3: Pol Roger | B3: Cuvée brut pour flight
A4: Billecart Salmon | B4: Brut, rosé, brut sous bois, blanc de blanc
A5: Louis Roederer | B5: Brut
A6: Larmandier bernier | B6: Terre de Vertus

Sheet FINALE
A1: Dom Perignon
A2: Krug | B2: Toutes les cuvées
A3: Billecart Salmon | B3: Cuvée millésimée, et le Clos Saint Hilaire en particulier
A4: Louis Roederer | B4: Cristal
A5: Pol Roger | B5: Cuvée Winston Churchill
A6: Ruinart | B6: Dom Ruinart
A7: Taittinger | B7: Comte de Champagne
A8: Dhondt Grellet | B8: Les Nogers, Le Bateau
A9: Egly Ouriet | B9: Les Crayères, Grand Cru Millésimé
A10: Jacques Selosse | B10: Toutes les cuvées
A11: Charles Heidsick | B11: Blanc des Millénaires
A12: Deutz | B12: Amour de Deutz
A13: Henri Giraud | B13: Ay fut de chene
A15: Blanc
A16: Vincent Dauvissat | B16: Chablis Grands Crus
A17: françois Raveneau | B17: Chablis Grands Crus
A18: Domaine Coche Dury | B18: Meursault 1er Cru, Corton Charlemagne
A19: Domaine des Comte lafon | B19: Meursault, Montrachet
A20: Domaine Roulot | B20: Meursault
A21: Domaine Bernard Bonin | B21: Meursault 1er Cru
A22: Domaine Arnaud Ente | B22: Meursault, Puligny Montrachet 1er Cru
A23: Domaine Bruno Colin | B23: Grand Cru
A24: Domaine Etienne Sauzet | B24: Grand Cru
A25: Domaine Pierre Yves Colin Morey | B25: Grand Cru
A26: Pierre girardin | B26: Grand Cru
A27: Domaine de la Vougeraie | B27: Corton Charlemagne
... A35: Armand Heitz | B35: Grands Crus
A37: Rouge
A38: Bordeaux
A39: Chateau Mouton Rotschild
A40: Chateau lafite Rotschild
A41: Chateau Latour
A42: Chateau Haut Brion
A43: Chateau Margaux
A44: Chateau Cheval Blanc
A45: Chateau Ausone
A46: Chateau Angelus
A47: Chateau Figeac
A48: Chateau Pavie
... A51: Bourgogne
...
